<?xml version="1.0" ?>
<!-- =================================================================================== -->
<!-- |    This document was autogenerated by xacro from lara8.xacro | -->
<!-- |    EDITING THIS FILE BY HAND IS NOT RECOMMENDED                                 | -->
<!-- =================================================================================== -->
<robot name="lara8" xmlns:controller="http://playerstage.sourceforge.net/gazebo/xmlschema/#controller" xmlns:interface="http://playerstage.sourceforge.net/gazebo/xmlschema/#interface" xmlns:sensor="http://playerstage.sourceforge.net/gazebo/xmlschema/#sensor">
	<!-- values not correct. 12/05/2022 heitmann-->
	<material name="white">
		<color rgba="1 1 1 1"/>
	</material>
	<!-- values not correct. 12/05/2022 heitmann-->
	<!-- ============================ BASE ================================= -->
	<link name="root_link">
	</link>
	<joint name="root_joint" type="fixed">
		<origin rpy="0 -1.57079632679 0" xyz="0 0 0"/>
		<axis xyz="0 0 1"/>
		<parent link="root_link"/>
		<child link="link0"/>
	</joint>
	<link name="link0">
		<inertial>
			<mass value="2.133"/>
			<origin rpy="0 0 0" xyz="0.0 0.0 0.0"/>
			<inertia ixx="0.0" ixy="0.0" ixz="0.0" iyy="0.0" iyz="0.0" izz="0.0"/>
		</inertial>
		<visual>
			<origin rpy="0 0 0" xyz="0 0 0"/>
			<geometry>
				<mesh filename="package://neura_robot_description/lara8/meshes/Link0_body.stl"/>
			</geometry>
			<material name="white"/>
		</visual>
		<visual>
			<origin rpy="0 0 0" xyz="0 0 0"/>
			<geometry>
				<mesh filename="package://neura_robot_description/lara8/meshes/Link0_connector.stl"/>
			</geometry>
			<material name="white"/>
		</visual>
		<collision>
			<origin rpy="0 0 0" xyz="0 0 0"/>
			<geometry>
				<mesh filename="package://neura_robot_description/lara8/collision/Link0_body.stl"/>
			</geometry>
			<material name="white"/>
		</collision>
	</link>
	<!-- ============================ DOF1 ================================= -->
	<joint name="joint1" type="revolute">
		<origin rpy="0 0 1.5707963267948966" xyz="0.26 0 0"/>
		<axis xyz="0 -1 0"/>
		<limit effort="204" lower="-3.14159" upper="3.14159" velocity="3.14159"/>
		<parent link="link0"/>
		<child link="link1"/>
	</joint>
	<link name="link1">
		<inertial>
			<mass value="16.083"/>
			<origin rpy="0 0 0" xyz="0.025552 0.064396 1.7e-05"/>
			<inertia ixx="0.123048" ixy="0.026103" ixz="1.3e-05" iyy="0.065328" iyz="7e-06" izz="0.140519"/>
		</inertial>
		<visual>
			<origin rpy="0 0 0" xyz="0 0 0"/>
			<geometry>
				<mesh filename="package://neura_robot_description/lara8/meshes/Link1_body.stl"/>
			</geometry>
			<material name="white"/>
		</visual>
		<visual>
			<origin rpy="0 0 0" xyz="0 0 0"/>
			<geometry>
				<mesh filename="package://neura_robot_description/lara8/meshes/Link1_rings.stl"/>
			</geometry>
			<material name="white"/>
		</visual>
		<collision>
			<origin rpy="0 0 0" xyz="0 0 0"/>
			<geometry>
				<mesh filename="package://neura_robot_description/lara8/collision/Link1_body.stl"/>
			</geometry>
			<material name="white"/>
		</collision>
	</link>
	<!-- ============================ DOF2 ================================= -->
	<joint name="joint2" type="revolute">
		<origin rpy="0 0 -4.8965276278067904e-12" xyz="0 0 0"/>
		<axis xyz="1 0 0"/>
		<limit effort="204" lower="-2.3492" upper="2.3492" velocity="2.3492"/>
		<parent link="link1"/>
		<child link="link2"/>
	</joint>
	<link name="link2">
		<inertial>
			<mass value="9.105"/>
			<origin rpy="0 0 0" xyz="0.143433 -0.26249999999999996 -5e-06"/>
			<inertia ixx="0.161953" ixy="-0.006786" ixz="3e-06" iyy="0.013421" iyz="3.9e-05" izz="0.157807"/>
		</inertial>
		<visual>
			<origin rpy="0 0 0" xyz="0 0 0"/>
			<geometry>
				<mesh filename="package://neura_robot_description/lara8/meshes/Link2_body.stl"/>
			</geometry>
			<material name="white"/>
		</visual>
		<collision>
			<origin rpy="0 0 0" xyz="0 0 0"/>
			<geometry>
				<mesh filename="package://neura_robot_description/lara8/collision/Link2_body.stl"/>
			</geometry>
			<material name="white"/>
		</collision>
	</link>
	<!-- ============================ DOF3 ================================= -->
	<joint name="joint3" type="revolute">
		<origin rpy="0 0 0" xyz="0 -0.6 0"/>
		<axis xyz="1 0 0"/>
		<limit effort="107" lower="-2.6093" upper="2.6093" velocity="2.6093"/>
		<parent link="link2"/>
		<child link="link3"/>
	</joint>
	<link name="link3">
		<inertial>
			<mass value="8.488"/>
			<origin rpy="0 0 0" xyz="0.0219 -0.056489 2.6e-05"/>
			<inertia ixx="0.038915" ixy="-0.008924" ixz="-4e-06" iyy="0.021874" iyz="7e-06" izz="0.046158"/>
		</inertial>
		<visual>
			<origin rpy="0 0 0" xyz="0 0 0"/>
			<geometry>
				<mesh filename="package://neura_robot_description/lara8/meshes/Link3_body.stl"/>
			</geometry>
			<material name="white"/>
		</visual>
		<visual>
			<origin rpy="0 0 0" xyz="0 0 0"/>
			<geometry>
				<mesh filename="package://neura_robot_description/lara8/meshes/Link3_rings.stl"/>
			</geometry>
			<material name="white"/>
		</visual>
		<collision>
			<origin rpy="0 0 0" xyz="0 0 0"/>
			<geometry>
				<mesh filename="package://neura_robot_description/lara8/collision/Link3_body.stl"/>
			</geometry>
			<material name="white"/>
		</collision>
	</link>
	<!-- ============================ DOF4 ================================= -->
	<joint name="joint4" type="revolute">
		<origin rpy="0 0 4.8965276278067904e-12" xyz="0 0 0"/>
		<axis xyz="0 -1 0"/>
		<limit effort="107" lower="-3.14159" upper="3.14159" velocity="3.14159"/>
		<parent link="link3"/>
		<child link="link4"/>
	</joint>
	<link name="link4">
		<inertial>
			<mass value="4.292"/>
			<origin rpy="0 0 0" xyz="0.06533 -0.4159170000000001 -8e-06"/>
			<inertia ixx="0.038962" ixy="0.009627" ixz="2e-06" iyy="0.008425" iyz="5e-06" izz="0.042366"/>
		</inertial>
		<visual>
			<origin rpy="0 0 0" xyz="0 0 0"/>
			<geometry>
				<mesh filename="package://neura_robot_description/lara8/meshes/Link4_body.stl"/>
			</geometry>
			<material name="white"/>
		</visual>
		<collision>
			<origin rpy="0 0 0" xyz="0 0 0"/>
			<geometry>
				<mesh filename="package://neura_robot_description/lara8/collision/Link4_body.stl"/>
			</geometry>
			<material name="white"/>
		</collision>
	</link>
	<!-- ============================ DOF5 ================================= -->
	<joint name="joint5" type="revolute">
		<origin rpy="0 0 -4.8965276278067904e-12" xyz="0 -0.7 0"/>
		<axis xyz="1 0 0"/>
		<limit effort="36" lower="-3.14159" upper="3.14159" velocity="3.14159"/>
		<parent link="link4"/>
		<child link="link5"/>
	</joint>
	<link name="link5">
		<inertial>
			<mass value="3.725"/>
			<origin rpy="0 0 0" xyz="0.017445 -0.047473 1.4e-05"/>
			<inertia ixx="0.009166" ixy="-0.002225" ixz="2e-06" iyy="0.005632" iyz="1e-06" izz="0.011521"/>
		</inertial>
		<visual>
			<origin rpy="0 0 0" xyz="0 0 0"/>
			<geometry>
				<mesh filename="package://neura_robot_description/lara8/meshes/Link5_body.stl"/>
			</geometry>
			<material name="white"/>
		</visual>
		<visual>
			<origin rpy="0 0 0" xyz="0 0 0"/>
			<geometry>
				<mesh filename="package://neura_robot_description/lara8/meshes/Link5_rings.stl"/>
			</geometry>
			<material name="white"/>
		</visual>
		<collision>
			<origin rpy="0 0 0" xyz="0 0 0"/>
			<geometry>
				<mesh filename="package://neura_robot_description/lara8/collision/Link5_body.stl"/>
			</geometry>
			<material name="white"/>
		</collision>
	</link>
	<!-- ============================ DOF6 ================================= -->
	<joint name="joint6" type="revolute">
		<origin rpy="0 0 4.8965276278067904e-12" xyz="0 0 0"/>
		<axis xyz="0 -1 0"/>
		<limit effort="36" lower="-3.14159" upper="3.14159" velocity="3.14159"/>
		<parent link="link5"/>
		<child link="link6"/>
	</joint>
	<link name="link6">
		<inertial>
			<mass value="0.932"/>
			<origin rpy="0 0 0" xyz="0.001157 -0.16727299999999998 0.000222"/>
			<inertia ixx="0.000587" ixy="-1.4e-05" ixz="4e-06" iyy="0.000637" iyz="3e-06" izz="0.000622"/>
		</inertial>
		<visual>
			<origin rpy="0 0 0" xyz="0 0 0"/>
			<geometry>
				<mesh filename="package://neura_robot_description/lara8/meshes/Link6_body.stl"/>
			</geometry>
			<material name="white"/>
		</visual>
		<collision>
			<origin rpy="0 0 0" xyz="0 0 0"/>
			<geometry>
				<mesh filename="package://neura_robot_description/lara8/collision/Link6_body.stl"/>
			</geometry>
			<material name="white"/>
		</collision>
	</link>





	<!-- ============================ Flange ================================= -->
	<link name="lara8_flange"/>
	<joint name="link6_to_flange" type="fixed">
		<origin rpy="1.5707963267948966 1.5707963267948966 0" xyz="0 -0.1735 0"/>
		<parent link="link6"/>
		<child link="lara8_flange"/>
	</joint>
	<!-- Create a fixed joint with a parameterized name. -->
	<joint name="measurement_tool_joint" type="fixed">
		<!-- The parent link must be read from the robot model it is attached to. -->
		<parent link="lara8_flange"/>
		<child link="measurement_tool"/>
		<!-- The tool is directly attached to the flange. -->
		<origin rpy="0 0 0" xyz="0 0 0"/>
	</joint>
	<link name="measurement_tool">
		<visual>
			<geometry>
				<!-- The path to the visual meshes in the package. -->
				<mesh filename="package://neura_robot_description/lara8/meshes/measurement_tool.stl"/>
			</geometry>
			<material name="white"/>
		</visual>
		<collision>
			<geometry>
				<!-- The path to the collision meshes in the package. -->
				<mesh filename="package://neura_robot_description/lara8/collision/measurement_tool.stl"/>
			</geometry>
			<material name="white"/>
		</collision>
	</link>
	<!-- TCP frame  -->
	<joint name="tcp_joint" type="fixed">
		<origin rpy="0 0 0" xyz="0 0.0 0.14"/>
		<parent link="measurement_tool"/>
		<child link="tcp"/>
	</joint>
	<link name="tcp"/>
	  
</robot>